test/testfailures.cpp(42): check equal (1, 0) failed
	1,  vs 0, 
suiteAssertEqual/ShouldFailByNoEqual: FAIL
test/testfailures.cpp(101): expected exception runtime_error not throw
suiteAssertException/ShouldFailByNoThrow: FAIL
test/testfailures.cpp(94): expected exception int not throw
suiteAssertException/ShouldFailByType: FAIL
test/testfailures.cpp(83): expected exception overflow_error("message") not throw
suiteAssertExceptionWithMessage/ShouldFailByChildException: FAIL
test/testfailures.cpp(69): expected exception runtime_error("hello") not throw
suiteAssertExceptionWithMessage/ShouldFailByNoThrow: FAIL
test/testfailures.cpp(76): check exception exception("message") failed
	catched exception: "another message"
suiteAssertExceptionWithMessage/ShouldFailByNotEqualMessage: FAIL
test/testfailures.cpp(62): expected exception int is not child of std::exception
suiteAssertExceptionWithMessage/ShouldFailByType: FAIL
test/testfailures.cpp(51): check not equal (1, 1) failed
	1,  vs 1, 
suiteAssertNe/ShouldFailByEqual: FAIL
exception from test ctor: setUp exception for checkpoint
test/testfailures.cpp(18): last checkpoint Test constructor
suiteCheckpoints/ExceptionInFixtureShouldCheckpointed: FAIL
unknown exception from test run
test/testfailures.cpp(7): last checkpoint Test run
suiteCheckpoints/UnhandledExceptionInTestShouldCheckpointed: FAIL
