test/testfailures.cpp(9): check equal (1, 0) failed
	1,  vs 0, 
suiteAssertEqual/ShouldFailByNoEqual: FAIL
test/testfailures.cpp(68): expected exception runtime_error not throw
suiteAssertException/ShouldFailByNoThrow: FAIL
test/testfailures.cpp(61): expected exception int not throw
suiteAssertException/ShouldFailByType: FAIL
test/testfailures.cpp(50): expected exception overflow_error("message") not throw
suiteAssertExceptionWithMessage/ShouldFailByChildException: FAIL
test/testfailures.cpp(36): expected exception runtime_error("hello") not throw
suiteAssertExceptionWithMessage/ShouldFailByNoThrow: FAIL
test/testfailures.cpp(43): check exception exception("message") failed
	catched exception: "another message"
suiteAssertExceptionWithMessage/ShouldFailByNotEqualMessage: FAIL
test/testfailures.cpp(29): expected exception int is not child of std::exception
suiteAssertExceptionWithMessage/ShouldFailByType: FAIL
test/testfailures.cpp(18): check not equal (1, 1) failed
	1,  vs 1, 
suiteAssertNe/ShouldFailByEqual: FAIL
